Workbook

Sheet dt_meta
A1: site | B1: start_date | C1: end_date | D1: name_dt | E1: name_local | F1: long_name_local | G1: units_local | H1: type | I1: time_char_format | J1: horizontal_id | K1: vertical_id | L1: replicate_id | M1: sensor_make | N1: sensor_model | O1: range_min | P1: range_max | Q1: diff_ref_max | R1: imputation_method | S1: name_era5 | T1: long_name_era5 | U1: units_era5 | V1: name_icos | W1: long_name_icos | X1: units_icos
A2: UK-AMO | B2: 34700 | C2: 47484 | D2: =E2 -> site | E2: =IF(J2="NA",V2,V2&"_"&J2&"_"&K2&"_"&L2) -> site | F2: site | H2: site | I2: NA | J2: NA | K2: NA | L2: NA | M2: NA | N2: NA | O2: =VLOOKUP($V2,naming_lookup!$C$1:$H$40,3,FALSE) -> #N/A | P2: =VLOOKUP($V2,naming_lookup!$C$1:$H$40,4,FALSE) -> #N/A | Q2: NA | R2: NA | S2: =VLOOKUP($V2,naming_lookup!$C$1:$H$40,5,FALSE) -> site | T2: =VLOOKUP($V2,naming_lookup!$C$1:$H$40,5,FALSE) -> site | U2: =VLOOKUP($V2,naming_lookup!$C$1:$H$40,6,FALSE) -> NA | V2: site | W2: site
A3: UK-AMO | B3: 34700 | C3: 47484 | D3: =E3 -> D_SNOW | E3: =IF(J3="NA",V3,V3&"_"&J3&"_"&K3&"_"&L3) -> D_SNOW | F3: Snow depth | G3: cm | H3: height | I3: NA | J3: NA | K3: NA | L3: NA | M3: Campbell | N3: CS-101 | O3: =VLOOKUP($V3,naming_lookup!$C$1:$H$40,3,FALSE) -> 0 | P3: =VLOOKUP($V3,naming_lookup!$C$1:$H$40,4,FALSE) -> 100 | Q3: 100 | R3: zero | S3: =VLOOKUP($V3,naming_lookup!$C$1:$H$40,5,FALSE) -> sd | T3: =VLOOKUP($V3,naming_lookup!$C$1:$H$40,5,FALSE) -> sd | U3: =VLOOKUP($V3,naming_lookup!$C$1:$H$40,6,FALSE) -> cm | V3: D_SNOW | W3: Snow depth | X3: cm
A4: UK-AMO | B4: 34700 | C4: 47484 | D4: =E4 -> D_SNOW_4_1_1 | E4: =IF(J4="NA",V4,V4&"_"&J4&"_"&K4&"_"&L4) -> D_SNOW_4_1_1 | F4: Snow depth | G4: cm | H4: height | I4: NA | J4: 4 | K4: 1 | L4: 1 | M4: Campbell | N4: CS-101 | O4: =VLOOKUP($V4,naming_lookup!$C$1:$H$40,3,FALSE) -> 0 | P4: =VLOOKUP($V4,naming_lookup!$C$1:$H$40,4,FALSE) -> 100 | Q4: 100 | R4: zero | S4: =VLOOKUP($V4,naming_lookup!$C$1:$H$40,5,FALSE) -> sd | T4: =VLOOKUP($V4,naming_lookup!$C$1:$H$40,5,FALSE) -> sd | U4: =VLOOKUP($V4,naming_lookup!$C$1:$H$40,6,FALSE) -> cm | V4: D_SNOW | W4: Snow depth | X4: cm
A5: UK-AMO | B5: 34700 | C5: 47484 | D5: =E5 -> DATECT | E5: DATECT | F5: timestamp | H5: time | I5: %Y-%m-%d %H:%M:%S | J5: NA | K5: NA | L5: NA | M5: NA | N5: NA | O5: =VLOOKUP($V5,naming_lookup!$C$1:$H$40,3,FALSE) -> #N/A | P5: =VLOOKUP($V5,naming_lookup!$C$1:$H$40,4,FALSE) -> #N/A | Q5: NA | R5: NA | S5: =VLOOKUP($V5,naming_lookup!$C$1:$H$40,5,FALSE) -> time | T5: =VLOOKUP($V5,naming_lookup!$C$1:$H$40,5,FALSE) -> time | U5: =VLOOKUP($V5,naming_lookup!$C$1:$H$40,6,FALSE) -> NA | V5: TIMESTAMP | W5: timestamp
A6: UK-AMO | B6: 34700 | C6: 47484 | D6: =E6 -> G | E6: =IF(J6="NA",V6,V6&"_"&J6&"_"&K6&"_"&L6) -> G | F6: Soil heat flux | G6: W m-2 | H6: energy flux | I6: NA | J6: NA | K6: NA | L6: NA | M6: Campbell | N6: CS-101 | O6: =VLOOKUP($V6,naming_lookup!$C$1:$H$40,3,FALSE) -> -30 | P6: =VLOOKUP($V6,naming_lookup!$C$1:$H$40,4,FALSE) -> 30 | Q6: 100 | R6: era5 | S6: =VLOOKUP($V6,naming_lookup!$C$1:$H$40,5,FALSE) -> ssrd | T6: =VLOOKUP($V6,naming_lookup!$C$1:$H$40,5,FALSE) -> ssrd | U6: =VLOOKUP($V6,naming_lookup!$C$1:$H$40,6,FALSE) -> W / m^2 | V6: G | W6: Soil heat flux | X6: W m-2
A7: UK-AMO | B7: 34700 | C7: 47484 | D7: =E7 -> G_4_1_1 | E7: =IF(J7="NA",V7,V7&"_"&J7&"_"&K7&"_"&L7) -> G_4_1_1 | F7: Soil heat flux | G7: W m-2 | H7: energy flux | I7: NA | J7: 4 | K7: 1 | L7: 1 | M7: Campbell | N7: CS-101 | O7: =VLOOKUP($V7,naming_lookup!$C$1:$H$40,3,FALSE) -> -30 | P7: =VLOOKUP($V7,naming_lookup!$C$1:$H$40,4,FALSE) -> 30 | Q7: 100 | R7: era5 | S7: =VLOOKUP($V7,naming_lookup!$C$1:$H$40,5,FALSE) -> ssrd | T7: =VLOOKUP($V7,naming_lookup!$C$1:$H$40,5,FALSE) -> ssrd | U7: =VLOOKUP($V7,naming_lookup!$C$1:$H$40,6,FALSE) -> W / m^2 | V7: G | W7: Soil heat flux | X7: W m-2
A8: UK-AMO | B8: 34700 | C8: 47484 | D8: =E8 -> G_4_1_2 | E8: =IF(J8="NA",V8,V8&"_"&J8&"_"&K8&"_"&L8) -> G_4_1_2 | F8: Soil heat flux | G8: W m-2 | H8: energy flux | I8: NA | J8: 4 | K8: 1 | L8: 2 | M8: Campbell | N8: CS-101 | O8: =VLOOKUP($V8,naming_lookup!$C$1:$H$40,3,FALSE) -> -30 | P8: =VLOOKUP($V8,naming_lookup!$C$1:$H$40,4,FALSE) -> 30 | Q8: 100 | R8: era5 | S8: =VLOOKUP($V8,naming_lookup!$C$1:$H$40,5,FALSE) -> ssrd | T8: =VLOOKUP($V8,naming_lookup!$C$1:$H$40,5,FALSE) -> ssrd | U8: =VLOOKUP($V8,naming_lookup!$C$1:$H$40,6,FALSE) -> W / m^2 | V8: G | W8: Soil heat flux | X8: W m-2
A9: UK-AMO | B9: 34700 | C9: 47484 | D9: =E9 -> LW_IN | E9: =IF(J9="NA",V9,V9&"_"&J9&"_"&K9&"_"&L9) -> LW_IN | F9: LongWave incoming radiation | G9: W m-2 | H9: arbitrary | I9: NA | J9: NA | K9: NA | L9: NA | M9: Campbell | N9: CS-101 | O9: =VLOOKUP($V9,naming_lookup!$C$1:$H$40,3,FALSE) -> 0 | P9: =VLOOKUP($V9,naming_lookup!$C$1:$H$40,4,FALSE) -> 1200 | Q9: 100 | R9: era5 | S9: =VLOOKUP($V9,naming_lookup!$C$1:$H$40,5,FALSE) -> strd | T9: =VLOOKUP($V9,naming_lookup!$C$1:$H$40,5,FALSE) -> strd | U9: =VLOOKUP($V9,naming_lookup!$C$1:$H$40,6,FALSE) -> W / m^2 | V9: LW_IN | W9: LongWave incoming radiation | X9: W m-2
A10: UK-AMO | B10: 34700 | C10: 47484 | D10: =E10 -> LW_IN_5_1_1 | E10: =IF(J10="NA",V10,V10&"_"&J10&"_"&K10&"_"&L10) -> LW_IN_5_1_1 | F10: LongWave incoming radiation | G10: W m-2 | H10: arbitrary | I10: NA | J10: 5 | K10: 1 | L10: 1 | M10: Campbell | N10: CS-101 | O10: =VLOOKUP($V10,naming_lookup!$C$1:$H$40,3,FALSE) -> 0 | P10: =VLOOKUP($V10,naming_lookup!$C$1:$H$40,4,FALSE) -> 1200 | Q10: 100 | R10: era5 | S10: =VLOOKUP($V10,naming_lookup!$C$1:$H$40,5,FALSE) -> strd | T10: =VLOOKUP($V10,naming_lookup!$C$1:$H$40,5,FALSE) -> strd | U10: =VLOOKUP($V10,naming_lookup!$C$1:$H$40,6,FALSE) -> W / m^2 | V10: LW_IN | W10: LongWave incoming radiation | X10: W m-2
A11: UK-AMO | B11: 34700 | C11: 47484 | D11: =E11 -> LW_OUT | E11: =IF(J11="NA",V11,V11&"_"&J11&"_"&K11&"_"&L11) -> LW_OUT | F11: LongWave outgoing radiation | G11: W m-2 | H11: energy flux | I11: NA | J11: NA | K11: NA | L11: NA | M11: Campbell | N11: CS-101 | O11: =VLOOKUP($V11,naming_lookup!$C$1:$H$40,3,FALSE) -> 0 | P11: =VLOOKUP($V11,naming_lookup!$C$1:$H$40,4,FALSE) -> 1000 | Q11: 100 | R11: era5 | S11: =VLOOKUP($V11,naming_lookup!$C$1:$H$40,5,FALSE) -> stru | T11: =VLOOKUP($V11,naming_lookup!$C$1:$H$40,5,FALSE) -> stru | U11: =VLOOKUP($V11,naming_lookup!$C$1:$H$40,6,FALSE) -> W / m^2 | V11: LW_OUT | W11: LongWave outgoing radiation | X11: W m-2
A12: UK-AMO | B12: 34700 | C12: 47484 | D12: =E12 -> LW_OUT_5_1_1 | E12: =IF(J12="NA",V12,V12&"_"&J12&"_"&K12&"_"&L12) -> LW_OUT_5_1_1 | F12: LongWave outgoing radiation | G12: W m-2 | H12: energy flux | I12: NA | J12: 5 | K12: 1 | L12: 1 | M12: Campbell | N12: CS-101 | O12: =VLOOKUP($V12,naming_lookup!$C$1:$H$40,3,FALSE) -> 0 | P12: =VLOOKUP($V12,naming_lookup!$C$1:$H$40,4,FALSE) -> 1000 | Q12: 100 | R12: era5 | S12: =VLOOKUP($V12,naming_lookup!$C$1:$H$40,5,FALSE) -> stru | T12: =VLOOKUP($V12,naming_lookup!$C$1:$H$40,5,FALSE) -> stru | U12: =VLOOKUP($V12,naming_lookup!$C$1:$H$40,6,FALSE) -> W / m^2 | V12: LW_OUT | W12: LongWave outgoing radiation | X12: W m-2
A13: UK-AMO | B13: 34700 | C13: 47484 | D13: =E13 -> LWS_4_1_1 | E13: =IF(J13="NA",V13,V13&"_"&J13&"_"&K13&"_"&L13) -> LWS_4_1_1 | F13: Leaf Wetness | G13: dimensionless | H13: arbitrary | I13: NA | J13: 4 | K13: 1 | L13: 1 | M13: Campbell | N13: CS-101 | O13: =VLOOKUP($V13,naming_lookup!$C$1:$H$40,3,FALSE) -> -99999 | P13: =VLOOKUP($V13,naming_lookup!$C$1:$H$40,4,FALSE) -> 99999 | Q13: 100 | R13: era5 | S13: =VLOOKUP($V13,naming_lookup!$C$1:$H$40,5,FALSE) -> rh | T13: =VLOOKUP($V13,naming_lookup!$C$1:$H$40,5,FALSE) -> rh | U13: =VLOOKUP($V13,naming_lookup!$C$1:$H$40,6,FALSE) -> 1 | V13: LWS | W13: Leaf Wetness | X13: dimensionless
A14: UK-AMO | B14: 34700 | C14: 47484 | D14: =E14 -> LWS_4_1_2 | E14: =IF(J14="NA",V14,V14&"_"&J14&"_"&K14&"_"&L14) -> LWS_4_1_2 | F14: Leaf Wetness | G14: dimensionless | H14: arbitrary | I14: NA | J14: 4 | K14: 1 | L14: 2 | M14: Campbell | N14: CS-101 | O14: =VLOOKUP($V14,naming_lookup!$C$1:$H$40,3,FALSE) -> -99999 | P14: =VLOOKUP($V14,naming_lookup!$C$1:$H$40,4,FALSE) -> 99999 | Q14: 100 | R14: era5 | S14: =VLOOKUP($V14,naming_lookup!$C$1:$H$40,5,FALSE) -> rh | T14: =VLOOKUP($V14,naming_lookup!$C$1:$H$40,5,FALSE) -> rh | U14: =VLOOKUP($V14,naming_lookup!$C$1:$H$40,6,FALSE) -> 1 | V14: LWS | W14: Leaf Wetness | X14: dimensionless
A15: UK-AMO | B15: 34700 | C15: 47484 | D15: =E15 -> NDVI_649IN_5_1_1 | E15: =IF(J15="NA",V15,V15&"_"&J15&"_"&K15&"_"&L15) -> NDVI_649IN_5_1_1 | F15: Photosynthetic photon flux density incoming @649 nm | G15: micromol m-2 s-1 | H15: energy flux | I15: NA | J15: 5 | K15: 1 | L15: 1 | M15: Campbell | N15: CS-101 | O15: =VLOOKUP($V15,naming_lookup!$C$1:$H$40,3,FALSE) -> 0 | P15: =VLOOKUP($V15,naming_lookup!$C$1:$H$40,4,FALSE) -> 500 | Q15: 100 | R15: nightzero | S15: =VLOOKUP($V15,naming_lookup!$C$1:$H$40,5,FALSE) -> ssrd | T15: =VLOOKUP($V15,naming_lookup!$C$1:$H$40,5,FALSE) -> ssrd | U15: =VLOOKUP($V15,naming_lookup!$C$1:$H$40,6,FALSE) -> micromol / m^2 / s | V15: NDVI_649IN | W15: Photosynthetic photon flux density incoming @649 nm | X15: micromol m-2 s-1
A16: UK-AMO | B16: 34700 | C16: 47484 | D16: =E16 -> NDVI_649OUT_5_1_1 | E16: =IF(J16="NA",V16,V16&"_"&J16&"_"&K16&"_"&L16) -> NDVI_649OUT_5_1_1 | F16: Photosynthetic photon flux density reflected @649 nm | G16: micromol m-2 s-1 | H16: energy flux | I16: NA | J16: 5 | K16: 1 | L16: 1 | M16: Campbell | N16: CS-101 | O16: =VLOOKUP($V16,naming_lookup!$C$1:$H$40,3,FALSE) -> 0 | P16: =VLOOKUP($V16,naming_lookup!$C$1:$H$40,4,FALSE) -> 500 | Q16: 100 | R16: nightzero | S16: =VLOOKUP($V16,naming_lookup!$C$1:$H$40,5,FALSE) -> ssru | T16: =VLOOKUP($V16,naming_lookup!$C$1:$H$40,5,FALSE) -> ssru | U16: =VLOOKUP($V16,naming_lookup!$C$1:$H$40,6,FALSE) -> micromol / m^2 / s | V16: NDVI_649OUT | W16: Photosynthetic photon flux density reflected @649 nm | X16: micromol m-2 s-1
A17: UK-AMO | B17: 34700 | C17: 47484 | D17: =E17 -> NDVI_797IN_5_1_1 | E17: =IF(J17="NA",V17,V17&"_"&J17&"_"&K17&"_"&L17) -> NDVI_797IN_5_1_1 | F17: Photosynthetic photon flux density incoming @797 nm | G17: micromol m-2 s-1 | H17: energy flux | I17: NA | J17: 5 | K17: 1 | L17: 1 | M17: Campbell | N17: CS-101 | O17: =VLOOKUP($V17,naming_lookup!$C$1:$H$40,3,FALSE) -> 0 | P17: =VLOOKUP($V17,naming_lookup!$C$1:$H$40,4,FALSE) -> 500 | Q17: 100 | R17: nightzero | S17: =VLOOKUP($V17,naming_lookup!$C$1:$H$40,5,FALSE) -> ssrd | T17: =VLOOKUP($V17,naming_lookup!$C$1:$H$40,5,FALSE) -> ssrd | U17: =VLOOKUP($V17,naming_lookup!$C$1:$H$40,6,FALSE) -> micromol / m^2 / s | V17: NDVI_797IN | W17: Photosynthetic photon flux density incoming @797 nm | X17: micromol m-2 s-1
A18: UK-AMO | B18: 34700 | C18: 47484 | D18: =E18 -> NDVI_797OUT_5_1_1 | E18: =IF(J18="NA",V18,V18&"_"&J18&"_"&K18&"_"&L18) -> NDVI_797OUT_5_1_1 | F18: Photosynthetic photon flux density reflected @797 nm | G18: micromol m-2 s-1 | H18: energy flux | I18: NA | J18: 5 | K18: 1 | L18: 1 | M18: Campbell | N18: CS-101 | O18: =VLOOKUP($V18,naming_lookup!$C$1:$H$40,3,FALSE) -> 0 | P18: =VLOOKUP($V18,naming_lookup!$C$1:$H$40,4,FALSE) -> 500 | Q18: 100 | R18: nightzero | S18: =VLOOKUP($V18,naming_lookup!$C$1:$H$40,5,FALSE) -> ssru | T18: =VLOOKUP($V18,naming_lookup!$C$1:$H$40,5,FALSE) -> ssru | U18: =VLOOKUP($V18,naming_lookup!$C$1:$H$40,6,FALSE) -> micromol / m^2 / s | V18: NDVI_797OUT | W18: Photosynthetic photon flux density reflected @797 nm | X18: micromol m-2 s-1
A19: UK-AMO | B19: 34700 | C19: 47484 | D19: =E19 -> P_12_1_1 | E19: =IF(J19="NA",V19,V19&"_"&J19&"_"&K19&"_"&L19) -> P_12_1_1 | F19: Precipitation | G19: mm/30 mins | H19: precipitation | I19: NA | J19: 12 | K19: 1 | L19: 1 | M19: Campbell | N19: CS-101 | O19: =VLOOKUP($V19,naming_lookup!$C$1:$H$40,3,FALSE) -> 0 | P19: =VLOOKUP($V19,naming_lookup!$C$1:$H$40,4,FALSE) -> 50 | Q19: 100 | R19: era5 | S19: =VLOOKUP($V19,naming_lookup!$C$1:$H$40,5,FALSE) -> tp | T19: =VLOOKUP($V19,naming_lookup!$C$1:$H$40,5,FALSE) -> tp | U19: =VLOOKUP($V19,naming_lookup!$C$1:$H$40,6,FALSE) -> mm | V19: P | W19: Precipitation | X19: mm/30 mins
A20: UK-AMO | B20: 34700 | C20: 47484 | D20: =E20 -> P_13_1_1 | E20: =IF(J20="NA",V20,V20&"_"&J20&"_"&K20&"_"&L20) -> P_13_1_1 | F20: Precipitation | G20: mm/30 mins | H20: precipitation | I20: NA | J20: 13 | K20: 1 | L20: 1 | M20: Campbell | N20: CS-101 | O20: =VLOOKUP($V20,naming_lookup!$C$1:$H$40,3,FALSE) -> 0 | P20: =VLOOKUP($V20,naming_lookup!$C$1:$H$40,4,FALSE) -> 50 | Q20: 100 | R20: era5 | S20: =VLOOKUP($V20,naming_lookup!$C$1:$H$40,5,FALSE) -> tp | T20: =VLOOKUP($V20,naming_lookup!$C$1:$H$40,5,FALSE) -> tp | U20: =VLOOKUP($V20,naming_lookup!$C$1:$H$40,6,FALSE) -> mm | V20: P | W20: Precipitation | X20: mm/30 mins
A21: UK-AMO | B21: 34700 | C21: 47484 | D21: =E21 -> PA_4_1_1 | E21: =IF(J21="NA",V21,V21&"_"&J21&"_"&K21&"_"&L21) -> PA_4_1_1 | F21: Atmospheric pressure | G21: kPa | H21: pressure | I21: NA | J21: 4 | K21: 1 | L21: 1 | M21: Campbell | N21: CS-101 | O21: =VLOOKUP($V21,naming_lookup!$C$1:$H$40,3,FALSE) -> 90 | P21: =VLOOKUP($V21,naming_lookup!$C$1:$H$40,4,FALSE) -> 130 | Q21: 100 | R21: era5 | S21: =VLOOKUP($V21,naming_lookup!$C$1:$H$40,5,FALSE) -> sp | T21: =VLOOKUP($V21,naming_lookup!$C$1:$H$40,5,FALSE) -> sp | U21: =VLOOKUP($V21,naming_lookup!$C$1:$H$40,6,FALSE) -> kPa | V21: PA | W21: Atmospheric pressure | X21: kPa
A22: UK-AMO | B22: 34700 | C22: 47484 | D22: =E22 -> PPFD_DIF | E22: =IF(J22="NA",V22,V22&"_"&J22&"_"&K22&"_"&L22) -> PPFD_DIF | F22: Photosynthetic photon flux density diffuse | G22: micromol m-2 s-1 | H22: energy flux | I22: NA | J22: NA | K22: NA | L22: NA | M22: Campbell | N22: CS-101 | O22: =VLOOKUP($V22,naming_lookup!$C$1:$H$40,3,FALSE) -> 0 | P22: =VLOOKUP($V22,naming_lookup!$C$1:$H$40,4,FALSE) -> 2200 | Q22: 100 | R22: era5 | S22: =VLOOKUP($V22,naming_lookup!$C$1:$H$40,5,FALSE) -> fdif | T22: =VLOOKUP($V22,naming_lookup!$C$1:$H$40,5,FALSE) -> fdif | U22: =VLOOKUP($V22,naming_lookup!$C$1:$H$40,6,FALSE) -> micromol / m^2 / s | V22: PPFD_DIF | W22: Photosynthetic photon flux density diffuse | X22: micromol m-2 s-1
A23: UK-AMO | B23: 34700 | C23: 47484 | D23: =E23 -> PPFD_DIF_4_1_1 | E23: =IF(J23="NA",V23,V23&"_"&J23&"_"&K23&"_"&L23) -> PPFD_DIF_4_1_1 | F23: Photosynthetic photon flux density diffuse | G23: micromol m-2 s-1 | H23: energy flux | I23: NA | J23: 4 | K23: 1 | L23: 1 | M23: Campbell | N23: CS-101 | O23: =VLOOKUP($V23,naming_lookup!$C$1:$H$40,3,FALSE) -> 0 | P23: =VLOOKUP($V23,naming_lookup!$C$1:$H$40,4,FALSE) -> 2200 | Q23: 100 | R23: era5 | S23: =VLOOKUP($V23,naming_lookup!$C$1:$H$40,5,FALSE) -> fdif | T23: =VLOOKUP($V23,naming_lookup!$C$1:$H$40,5,FALSE) -> fdif | U23: =VLOOKUP($V23,naming_lookup!$C$1:$H$40,6,FALSE) -> micromol / m^2 / s | V23: PPFD_DIF | W23: Photosynthetic photon flux density diffuse | X23: micromol m-2 s-1
A24: UK-AMO | B24: 34700 | C24: 47484 | D24: =E24 -> PPFD_IN_4_1_1 | E24: =IF(J24="NA",V24,V24&"_"&J24&"_"&K24&"_"&L24) -> PPFD_IN_4_1_1 | F24: Photosynthetic photon flux density incoming | G24: micromol m-2 s-1 | H24: energy flux | I24: NA | J24: 4 | K24: 1 | L24: 1 | M24: Campbell | N24: CS-101 | O24: =VLOOKUP($V24,naming_lookup!$C$1:$H$40,3,FALSE) -> 0 | P24: =VLOOKUP($V24,naming_lookup!$C$1:$H$40,4,FALSE) -> 2200 | Q24: 100 | R24: era5 | S24: =VLOOKUP($V24,naming_lookup!$C$1:$H$40,5,FALSE) -> ssrd | T24: =VLOOKUP($V24,naming_lookup!$C$1:$H$40,5,FALSE) -> ssrd | U24: =VLOOKUP($V24,naming_lookup!$C$1:$H$40,6,FALSE) -> micromol / m^2 / s | V24: PPFD_IN | W24: Photosynthetic photon flux density incoming | X24: micromol m-2 s-1
A25: UK-AMO | B25: 34700 | C25: 47484 | D25: =E25 -> PPFD_IN_5_1_1 | E25: =IF(J25="NA",V25,V25&"_"&J25&"_"&K25&"_"&L25) -> PPFD_IN_5_1_1 | F25: Photosynthetic photon flux density incoming | G25: micromol m-2 s-1 | H25: energy flux | I25: NA | J25: 5 | K25: 1 | L25: 1 | M25: Campbell | N25: CS-101 | O25: =VLOOKUP($V25,naming_lookup!$C$1:$H$40,3,FALSE) -> 0 | P25: =VLOOKUP($V25,naming_lookup!$C$1:$H$40,4,FALSE) -> 2200 | Q25: 100 | R25: era5 | S25: =VLOOKUP($V25,naming_lookup!$C$1:$H$40,5,FALSE) -> ssrd | T25: =VLOOKUP($V25,naming_lookup!$C$1:$H$40,5,FALSE) -> ssrd | U25: =VLOOKUP($V25,naming_lookup!$C$1:$H$40,6,FALSE) -> micromol / m^2 / s | V25: PPFD_IN | W25: Photosynthetic photon flux density incoming | X25: micromol m-2 s-1
A26: UK-AMO | B26: 34700 | C26: 47484 | D26: =E26 -> PPFD_IN_5_1_2 | E26: =IF(J26="NA",V26,V26&"_"&J26&"_"&K26&"_"&L26) -> PPFD_IN_5_1_2 | F26: Photosynthetic photon flux density incoming | G26: micromol m-2 s-1 | H26: energy flux | I26: NA | J26: 5 | K26: 1 | L26: 2 | M26: Campbell | N26: CS-101 | O26: =VLOOKUP($V26,naming_lookup!$C$1:$H$40,3,FALSE) -> 0 | P26: =VLOOKUP($V26,naming_lookup!$C$1:$H$40,4,FALSE) -> 2200 | Q26: 100 | R26: era5 | S26: =VLOOKUP($V26,naming_lookup!$C$1:$H$40,5,FALSE) -> ssrd | T26: =VLOOKUP($V26,naming_lookup!$C$1:$H$40,5,FALSE) -> ssrd | U26: =VLOOKUP($V26,naming_lookup!$C$1:$H$40,6,FALSE) -> micromol / m^2 / s | V26: PPFD_IN | W26: Photosynthetic photon flux density incoming | X26: micromol m-2 s-1
A27: UK-AMO | B27: 34700 | C27: 47484 | D27: =E27 -> PPFD_OUT | E27: =IF(J27="NA",V27,V27&"_"&J27&"_"&K27&"_"&L27) -> PPFD_OUT | F27: Photosynthetic photon flux density outgoing | G27: micromol m-2 s-1 | H27: energy flux | I27: NA | J27: NA | K27: NA | L27: NA | M27: Campbell | N27: CS-101 | O27: =VLOOKUP($V27,naming_lookup!$C$1:$H$40,3,FALSE) -> 0 | P27: =VLOOKUP($V27,naming_lookup!$C$1:$H$40,4,FALSE) -> 2200 | Q27: 100 | R27: era5 | S27: =VLOOKUP($V27,naming_lookup!$C$1:$H$40,5,FALSE) -> ssru | T27: =VLOOKUP($V27,naming_lookup!$C$1:$H$40,5,FALSE) -> ssru | U27: =VLOOKUP($V27,naming_lookup!$C$1:$H$40,6,FALSE) -> micromol / m^2 / s | V27: PPFD_OUT | W27: Photosynthetic photon flux density outgoing | X27: micromol m-2 s-1
A28: UK-AMO | B28: 34700 | C28: 47484 | D28: =E28 -> PPFD_OUT_5_1_1 | E28: =IF(J28="NA",V28,V28&"_"&J28&"_"&K28&"_"&L28) -> PPFD_OUT_5_1_1 | F28: Photosynthetic photon flux density outgoing | G28: micromol m-2 s-1 | H28: energy flux | I28: NA | J28: 5 | K28: 1 | L28: 1 | M28: Campbell | N28: CS-101 | O28: =VLOOKUP($V28,naming_lookup!$C$1:$H$40,3,FALSE) -> 0 | P28: =VLOOKUP($V28,naming_lookup!$C$1:$H$40,4,FALSE) -> 2200 | Q28: 100 | R28: era5 | S28: =VLOOKUP($V28,naming_lookup!$C$1:$H$40,5,FALSE) -> ssru | T28: =VLOOKUP($V28,naming_lookup!$C$1:$H$40,5,FALSE) -> ssru | U28: =VLOOKUP($V28,naming_lookup!$C$1:$H$40,6,FALSE) -> micromol / m^2 / s | V28: PPFD_OUT | W28: Photosynthetic photon flux density outgoing | X28: micromol m-2 s-1
A29: UK-AMO | B29: 34700 | C29: 47484 | D29: =E29 -> RG_4_1_0 | E29: =IF(J29="NA",V29,V29&"_"&J29&"_"&K29&"_"&L29) -> RG_4_1_0 | F29: Total global radiation | G29: W m-2 | H29: energy flux | I29: NA | J29: 4 | K29: 1 | L29: 0 | M29: Campbell | N29: CS-101 | O29: =VLOOKUP($V29,naming_lookup!$C$1:$H$40,3,FALSE) -> 0 | P29: =VLOOKUP($V29,naming_lookup!$C$1:$H$40,4,FALSE) -> 1200 | Q29: 100 | R29: era5 | S29: =VLOOKUP($V29,naming_lookup!$C$1:$H$40,5,FALSE) -> ssrd | T29: =VLOOKUP($V29,naming_lookup!$C$1:$H$40,5,FALSE) -> ssrd | U29: =VLOOKUP($V29,naming_lookup!$C$1:$H$40,6,FALSE) -> W / m^2 | V29: RG | W29: Total global radiation | X29: W m-2
A30: UK-AMO | B30: 34700 | C30: 47484 | D30: =E30 -> RH_2_1_1 | E30: =IF(J30="NA",V30,V30&"_"&J30&"_"&K30&"_"&L30) -> RH_2_1_1 | F30: Relative humidity | G30: % | H30: humidity | I30: NA | J30: 2 | K30: 1 | L30: 1 | M30: Campbell | N30: CS-101 | O30: =VLOOKUP($V30,naming_lookup!$C$1:$H$40,3,FALSE) -> 30 | P30: =VLOOKUP($V30,naming_lookup!$C$1:$H$40,4,FALSE) -> 120 | Q30: 100 | R30: era5 | S30: =VLOOKUP($V30,naming_lookup!$C$1:$H$40,5,FALSE) -> rh | T30: =VLOOKUP($V30,naming_lookup!$C$1:$H$40,5,FALSE) -> rh | U30: =VLOOKUP($V30,naming_lookup!$C$1:$H$40,6,FALSE) -> percent | V30: RH | W30: Relative humidity | X30: %
A31: UK-AMO | B31: 34700 | C31: 47484 | D31: =E31 -> RH_4_1_1 | E31: =IF(J31="NA",V31,V31&"_"&J31&"_"&K31&"_"&L31) -> RH_4_1_1 | F31: Relative humidity | G31: % | H31: humidity | I31: NA | J31: 4 | K31: 1 | L31: 1 | M31: Campbell | N31: CS-101 | O31: =VLOOKUP($V31,naming_lookup!$C$1:$H$40,3,FALSE) -> 30 | P31: =VLOOKUP($V31,naming_lookup!$C$1:$H$40,4,FALSE) -> 120 | Q31: 100 | R31: era5 | S31: =VLOOKUP($V31,naming_lookup!$C$1:$H$40,5,FALSE) -> rh | T31: =VLOOKUP($V31,naming_lookup!$C$1:$H$40,5,FALSE) -> rh | U31: =VLOOKUP($V31,naming_lookup!$C$1:$H$40,6,FALSE) -> percent | V31: RH | W31: Relative humidity | X31: %
A32: UK-AMO | B32: 34700 | C32: 47484 | D32: =E32 -> RH_7_1_1 | E32: =IF(J32="NA",V32,V32&"_"&J32&"_"&K32&"_"&L32) -> RH_7_1_1 | F32: Relative humidity | G32: % | H32: humidity | I32: NA | J32: 7 | K32: 1 | L32: 1 | M32: Campbell | N32: CS-101 | O32: =VLOOKUP($V32,naming_lookup!$C$1:$H$40,3,FALSE) -> 30 | P32: =VLOOKUP($V32,naming_lookup!$C$1:$H$40,4,FALSE) -> 120 | Q32: 100 | R32: era5 | S32: =VLOOKUP($V32,naming_lookup!$C$1:$H$40,5,FALSE) -> rh | T32: =VLOOKUP($V32,naming_lookup!$C$1:$H$40,5,FALSE) -> rh | U32: =VLOOKUP($V32,naming_lookup!$C$1:$H$40,6,FALSE) -> percent | V32: RH | W32: Relative humidity | X32: %
A33: UK-AMO | B33: 34700 | C33: 47484 | D33: =E33 -> RN_5_1_1 | E33: =IF(J33="NA",V33,V33&"_"&J33&"_"&K33&"_"&L33) -> RN_5_1_1 | F33: Net radiation | G33: W m-2 | H33: energy flux | I33: NA | J33: 5 | K33: 1 | L33: 1 | M33: Campbell | N33: CS-101 | O33: =VLOOKUP($V33,naming_lookup!$C$1:$H$40,3,FALSE) -> -500 | P33: =VLOOKUP($V33,naming_lookup!$C$1:$H$40,4,FALSE) -> 1200 | Q33: 100 | R33: era5 | S33: =VLOOKUP($V33,naming_lookup!$C$1:$H$40,5,FALSE) -> rn | T33: =VLOOKUP($V33,naming_lookup!$C$1:$H$40,5,FALSE) -> rn | U33: =VLOOKUP($V33,naming_lookup!$C$1:$H$40,6,FALSE) -> W / m^2 | V33: RN | W33: Net radiation | X33: W m-2
A34: UK-AMO | B34: 34700 | C34: 47484 | D34: =E34 -> SW_IN | E34: =IF(J34="NA",V34,V34&"_"&J34&"_"&K34&"_"&L34) -> SW_IN | F34: Shortwave incoming radiation | G34: W m-2 | H34: energy flux | I34: NA | J34: NA | K34: NA | L34: NA | M34: Campbell | N34: CS-101 | O34: =VLOOKUP($V34,naming_lookup!$C$1:$H$40,3,FALSE) -> 0 | P34: =VLOOKUP($V34,naming_lookup!$C$1:$H$40,4,FALSE) -> 1200 | Q34: 100 | R34: era5 | S34: =VLOOKUP($V34,naming_lookup!$C$1:$H$40,5,FALSE) -> ssrd | T34: =VLOOKUP($V34,naming_lookup!$C$1:$H$40,5,FALSE) -> ssrd | U34: =VLOOKUP($V34,naming_lookup!$C$1:$H$40,6,FALSE) -> W / m^2 | V34: SW_IN | W34: Shortwave incoming radiation | X34: W m-2
A35: UK-AMO | B35: 34700 | C35: 47484 | D35: =E35 -> SW_IN_5_1_1 | E35: =IF(J35="NA",V35,V35&"_"&J35&"_"&K35&"_"&L35) -> SW_IN_5_1_1 | F35: Shortwave incoming radiation | G35: W m-2 | H35: energy flux | I35: NA | J35: 5 | K35: 1 | L35: 1 | M35: Campbell | N35: CS-101 | O35: =VLOOKUP($V35,naming_lookup!$C$1:$H$40,3,FALSE) -> 0 | P35: =VLOOKUP($V35,naming_lookup!$C$1:$H$40,4,FALSE) -> 1200 | Q35: 100 | R35: era5 | S35: =VLOOKUP($V35,naming_lookup!$C$1:$H$40,5,FALSE) -> ssrd | T35: =VLOOKUP($V35,naming_lookup!$C$1:$H$40,5,FALSE) -> ssrd | U35: =VLOOKUP($V35,naming_lookup!$C$1:$H$40,6,FALSE) -> W / m^2 | V35: SW_IN | W35: Shortwave incoming radiation | X35: W m-2
A36: UK-AMO | B36: 34700 | C36: 47484 | D36: =E36 -> SW_IN_7_1_1 | E36: =IF(J36="NA",V36,V36&"_"&J36&"_"&K36&"_"&L36) -> SW_IN_7_1_1 | F36: Shortwave incoming radiation | G36: W m-2 | H36: energy flux | I36: NA | J36: 7 | K36: 1 | L36: 1 | M36: Campbell | N36: CS-101 | O36: =VLOOKUP($V36,naming_lookup!$C$1:$H$40,3,FALSE) -> 0 | P36: =VLOOKUP($V36,naming_lookup!$C$1:$H$40,4,FALSE) -> 1200 | Q36: 100 | R36: era5 | S36: =VLOOKUP($V36,naming_lookup!$C$1:$H$40,5,FALSE) -> ssrd | T36: =VLOOKUP($V36,naming_lookup!$C$1:$H$40,5,FALSE) -> ssrd | U36: =VLOOKUP($V36,naming_lookup!$C$1:$H$40,6,FALSE) -> W / m^2 | V36: SW_IN | W36: Shortwave incoming radiation | X36: W m-2
A37: UK-AMO | B37: 34700 | C37: 47484 | D37: =E37 -> SW_OUT | E37: =IF(J37="NA",V37,V37&"_"&J37&"_"&K37&"_"&L37) -> SW_OUT | F37: Shortwave outgoing radiation | G37: W m-2 | H37: energy flux | I37: NA | J37: NA | K37: NA | L37: NA | M37: Campbell | N37: CS-101 | O37: =VLOOKUP($V37,naming_lookup!$C$1:$H$40,3,FALSE) -> 0 | P37: =VLOOKUP($V37,naming_lookup!$C$1:$H$40,4,FALSE) -> 300 | Q37: 100 | R37: era5 | S37: =VLOOKUP($V37,naming_lookup!$C$1:$H$40,5,FALSE) -> ssru | T37: =VLOOKUP($V37,naming_lookup!$C$1:$H$40,5,FALSE) -> ssru | U37: =VLOOKUP($V37,naming_lookup!$C$1:$H$40,6,FALSE) -> W / m^2 | V37: SW_OUT | W37: Shortwave outgoing radiation | X37: W m-2
A38: UK-AMO | B38: 34700 | C38: 47484 | D38: =E38 -> SW_OUT_5_1_1 | E38: =IF(J38="NA",V38,V38&"_"&J38&"_"&K38&"_"&L38) -> SW_OUT_5_1_1 | F38: Shortwave outgoing radiation | G38: W m-2 | H38: energy flux | I38: NA | J38: 5 | K38: 1 | L38: 1 | M38: Campbell | N38: CS-101 | O38: =VLOOKUP($V38,naming_lookup!$C$1:$H$40,3,FALSE) -> 0 | P38: =VLOOKUP($V38,naming_lookup!$C$1:$H$40,4,FALSE) -> 300 | Q38: 100 | R38: era5 | S38: =VLOOKUP($V38,naming_lookup!$C$1:$H$40,5,FALSE) -> ssru | T38: =VLOOKUP($V38,naming_lookup!$C$1:$H$40,5,FALSE) -> ssru | U38: =VLOOKUP($V38,naming_lookup!$C$1:$H$40,6,FALSE) -> W / m^2 | V38: SW_OUT | W38: Shortwave outgoing radiation | X38: W m-2
A39: UK-AMO | B39: 34700 | C39: 47484 | D39: =E39 -> SWC | E39: =IF(J39="NA",V39,V39&"_"&J39&"_"&K39&"_"&L39) -> SWC | F39: Soil water content | G39: % | H39: soil moisture | I39: NA | J39: NA | K39: NA | L39: NA | M39: Campbell | N39: CS-101 | O39: =VLOOKUP($V39,naming_lookup!$C$1:$H$40,3,FALSE) -> 0 | P39: =VLOOKUP($V39,naming_lookup!$C$1:$H$40,4,FALSE) -> 100 | Q39: 100 | R39: era5 | S39: =VLOOKUP($V39,naming_lookup!$C$1:$H$40,5,FALSE) -> swvl1 | T39: =VLOOKUP($V39,naming_lookup!$C$1:$H$40,5,FALSE) -> swvl1 | U39: =VLOOKUP($V39,naming_lookup!$C$1:$H$40,6,FALSE) -> percent | V39: SWC | W39: Soil water content | X39: %
A40: UK-AMO | B40: 34700 | C40: 47484 | D40: =E40 -> SWC_4_1_1 | E40: =IF(J40="NA",V40,V40&"_"&J40&"_"&K40&"_"&L40) -> SWC_4_1_1 | F40: Soil water content | G40: % | H40: soil moisture | I40: NA | J40: 4 | K40: 1 | L40: 1 | M40: Campbell | N40: CS-101 | O40: =VLOOKUP($V40,naming_lookup!$C$1:$H$40,3,FALSE) -> 0 | P40: =VLOOKUP($V40,naming_lookup!$C$1:$H$40,4,FALSE) -> 100 | Q40: 100 | R40: era5 | S40: =VLOOKUP($V40,naming_lookup!$C$1:$H$40,5,FALSE) -> swvl1 | T40: =VLOOKUP($V40,naming_lookup!$C$1:$H$40,5,FALSE) -> swvl1 | U40: =VLOOKUP($V40,naming_lookup!$C$1:$H$40,6,FALSE) -> percent | V40: SWC | W40: Soil water content | X40: %
...

Sheet naming_lookup
A1: variable | B1: name_local | C1: name_icos | D1: units_icos | E1: range_min | F1: range_max | G1: name_era5 | H1: units_era5
A2: Soil temperature | B2: TS | C2: TS | D2: degree_C | E2: =VLOOKUP($C2,dt_var_naming!$A$2:$F$27,5,FALSE) -> -20 | F2: =VLOOKUP($C2,dt_var_naming!$A$2:$F$27,6,FALSE) -> 50 | G2: stl1 | H2: degree_C
A3: site | B3: site | C3: site | D3: NA | E3: =VLOOKUP($C3,dt_var_naming!$A$2:$F$27,5,FALSE) -> #N/A | F3: =VLOOKUP($C3,dt_var_naming!$A$2:$F$27,6,FALSE) -> #N/A | G3: site | H3: NA
A4: Time | B4: DATECT | C4: TIMESTAMP | D4: NA | E4: =VLOOKUP($C4,dt_var_naming!$A$2:$F$27,5,FALSE) -> #N/A | F4: =VLOOKUP($C4,dt_var_naming!$A$2:$F$27,6,FALSE) -> #N/A | G4: time | H4: NA
A5: Soil water content | B5: SWC | C5: SWC | D5: percent | E5: =VLOOKUP($C5,dt_var_naming!$A$2:$F$27,5,FALSE) -> 0 | F5: =VLOOKUP($C5,dt_var_naming!$A$2:$F$27,6,FALSE) -> 100 | G5: swvl1 | H5: percent
A6: Soil heat flux | B6: G | C6: G | D6: W / m^2 | E6: =VLOOKUP($C6,dt_var_naming!$A$2:$F$27,5,FALSE) -> -30 | F6: =VLOOKUP($C6,dt_var_naming!$A$2:$F$27,6,FALSE) -> 30 | G6: ssrd | H6: W / m^2
A7: Water table depth | B7: WTD | C7: WTD | D7: m | E7: =VLOOKUP($C7,dt_var_naming!$A$2:$F$27,5,FALSE) -> -10 | F7: =VLOOKUP($C7,dt_var_naming!$A$2:$F$27,6,FALSE) -> 10 | G7: swvl1 | H7: m
A8: Water table depth | B8: WTD_4_1_1 | C8: WTD | D8: m | E8: =VLOOKUP($C8,dt_var_naming!$A$2:$F$27,5,FALSE) -> -10 | F8: =VLOOKUP($C8,dt_var_naming!$A$2:$F$27,6,FALSE) -> 10 | G8: swvl1 | H8: m
A9: Air pressure | B9: PA_4_1_1 | C9: PA | D9: kPa | E9: =VLOOKUP($C9,dt_var_naming!$A$2:$F$27,5,FALSE) -> 90 | F9: =VLOOKUP($C9,dt_var_naming!$A$2:$F$27,6,FALSE) -> 130 | G9: sp | H9: kPa
A10: ShortWave incoming radiation | B10: SW_IN | C10: SW_IN | D10: W / m^2 | E10: =VLOOKUP($C10,dt_var_naming!$A$2:$F$27,5,FALSE) -> 0 | F10: =VLOOKUP($C10,dt_var_naming!$A$2:$F$27,6,FALSE) -> 1200 | G10: ssrd | H10: W / m^2
A11: ShortWave outgoing radiation | B11: SW_OUT | C11: SW_OUT | D11: W / m^2 | E11: =VLOOKUP($C11,dt_var_naming!$A$2:$F$27,5,FALSE) -> 0 | F11: =VLOOKUP($C11,dt_var_naming!$A$2:$F$27,6,FALSE) -> 300 | G11: ssru | H11: W / m^2
A12: LongWave incoming radiation | B12: LW_IN | C12: LW_IN | D12: W / m^2 | E12: =VLOOKUP($C12,dt_var_naming!$A$2:$F$27,5,FALSE) -> 0 | F12: =VLOOKUP($C12,dt_var_naming!$A$2:$F$27,6,FALSE) -> 1200 | G12: strd | H12: W / m^2
A13: LongWave outgoing radiation | B13: LW_OUT | C13: LW_OUT | D13: W / m^2 | E13: =VLOOKUP($C13,dt_var_naming!$A$2:$F$27,5,FALSE) -> 0 | F13: =VLOOKUP($C13,dt_var_naming!$A$2:$F$27,6,FALSE) -> 1000 | G13: stru | H13: W / m^2
... A38: Photosynthetic photon flux density reflected @797 nm | B38: NDVI_797OUT_5_1_1 | C38: NDVI_797OUT | D38: micromol / m^2 / s | E38: =VLOOKUP($C38,dt_var_naming!$A$2:$F$27,5,FALSE) -> 0 | F38: =VLOOKUP($C38,dt_var_naming!$A$2:$F$27,6,FALSE) -> 500 | G38: ssru | H38: micromol / m^2 / s
A39: Leaf Wetness | B39: LWS_4_1_1 | C39: LWS | D39: 1 | E39: =VLOOKUP($C39,dt_var_naming!$A$2:$F$27,5,FALSE) -> -99999 | F39: =VLOOKUP($C39,dt_var_naming!$A$2:$F$27,6,FALSE) -> 99999 | G39: rh | H39: 1
A40: Leaf Wetness | B40: LWS_4_1_2 | C40: LWS | D40: 1 | E40: =VLOOKUP($C40,dt_var_naming!$A$2:$F$27,5,FALSE) -> -99999 | F40: =VLOOKUP($C40,dt_var_naming!$A$2:$F$27,6,FALSE) -> 99999 | G40: rh | H40: 1

Sheet dt_var_naming
A1: name_local | B1: long_name_local | C1: units | D1: type | E1: range_min | F1: range_max | G1: name_icos | H1: long_name_icos | I1: units_icos | J1: name_cf | K1: long_name_cf | L1: units_cf | M1: name_era5 | N1: long_name_era5 | O1: units_era5
A2: D_SNOW | B2: Snow depth | C2: m | D2: height | E2: 0 | F2: 100 | G2: D_SNOW | H2: Snow depth | I2: cm | J2: surface_snow_thickness | K2: Surface snow refers to the snow on the solid ground or on surface ice cover, but excludes, for example, falling snowflakes and snow on plants. "Thickness" means the vertical extent of a layer. Unless indicated in the cell_methods attribute, a quantity is assumed to apply to the whole area of each horizontal grid box. Previously, the qualifier where_type was used to specify that the quantity applies only to the part of the grid box of the named type. Names containing the where_type qualifier are deprecated and newly created data should use the cell_methods attribute to indicate the horizontal area to which the quantity applies. | L2: m | M2: =VLOOKUP(A2,naming_lookup!$C$1:$G$40,3,FALSE) -> 0 | N2: _x000D_ This parameter is the depth of snow from the snow-covered area of a grid box._x000D_ _x000D_ Its units are metres of water equivalent, so it is the depth the water would have if the snow melted and was spread evenly over the whole grid box. The ECMWF Integrated Forecast System represents snow as a single additional layer over the uppermost soil level. The snow may cover all or part of the grid box._x000D_ _x000D_ See further information. [NOTE: See 228141 for the equivalent parameter in "kg m-2"] | O2: m of water equivalent
A3: DATECT | B3: timestamp in POSIX format | C3: NA | D3: time | G3: TIMESTAMP | H3: timestamp in POSIX format | J3: timestamp | K3: timestamp in POSIX format | L3: NA | M3: =VLOOKUP(A3,naming_lookup!$C$1:$G$40,3,FALSE) -> #N/A | N3: timestamp in POSIX format | O3: NA
A4: G | B4: Soil heat flux | C4: W m^2 | D4: energy flux | E4: -30 | F4: 30 | G4: G | H4: Soil heat flux | I4: W m-2 | J4: downward_heat_flux_at_ground_level_in_soil | K4: ground_level means the land surface (beneath the snow and surface water, if any). 'Downward' indicates a vector component which is positive when directed downward (negative upward). In accordance with common usage in geophysical disciplines, 'flux' implies per unit area, called 'flux density' in physics. | L4: W m-2 | M4: =VLOOKUP(A4,naming_lookup!$C$1:$G$40,3,FALSE) -> -30
A5: LW_IN | B5: LongWave incoming radiation | C5: W / m^2 | D5: energy flux | E5: 0 | F5: 1200 | G5: LW_IN | H5: Incoming Longwave radiation (in the range from 4 to 50 micron) | I5: W m-2 | J5: surface_downwelling_longwave_flux_in_air | K5: The surface called "surface" means the lower boundary of the atmosphere. Downwelling radiation is radiation from above. It does not mean "net downward". The sign convention is that "upwelling" is positive upwards and "downwelling" is positive downwards. The term "longwave" means longwave radiation. When thought of as being incident on a surface, a radiative flux is sometimes called "irradiance". In addition, it is identical with the quantity measured by a cosine-collector light-meter and sometimes called "vector irradiance". In accordance with common usage in geophysical disciplines, "flux" implies per unit area, called "flux density" in physics. | L5: W m-2 | M5: =VLOOKUP(A5,naming_lookup!$C$1:$G$40,3,FALSE) -> 0 | N5: This parameter is the amount of thermal (also known as longwave or terrestrial) radiation emitted by the atmosphere and clouds that reaches a horizontal plane at the surface of the Earth._x000D_ _x000D_ The surface of the Earth emits thermal radiation, some of which is absorbed by the atmosphere and clouds. The atmosphere and clouds likewise emit thermal radiation in all directions, some of which reaches the surface (represented by this parameter). See further documentation._x000D_ _x000D_ This parameter is accumulated over a particular time period which depends on the data extracted. The units are joules per square metre (J m-2). To convert to watts per square metre (W m-2), the accumulated values should be divided by the accumulation period expressed in seconds. The ECMWF convention for vertical fluxes is positive downwards. | O5: J m-2
A6: LW_OUT | B6: LongWave outgoing radiation | C6: W / m^2 | D6: energy flux | E6: 0 | F6: 1000 | G6: LW_OUT | H6: Outgoing Longwave radiation (in the range from 4 to 50 micron) | I6: W m-2 | J6: surface_upwelling_longwave_flux_in_air | K6: The surface called "surface" means the lower boundary of the atmosphere. The term "longwave" means longwave radiation. Upwelling radiation is radiation from below. It does not mean "net upward". The sign convention is that "upwelling" is positive upwards and "downwelling" is positive downwards. When thought of as being incident on a surface, a radiative flux is sometimes called "irradiance". In addition, it is identical with the quantity measured by a cosine-collector light-meter and sometimes called "vector irradiance". In accordance with common usage in geophysical disciplines, "flux" implies per unit area, called "flux density" in physics. | L6: W m-2 | M6: =VLOOKUP(A6,naming_lookup!$C$1:$G$40,3,FALSE) -> 0
A7: LWS | B7: Leaf Wetness | C7: dimensionless | D7: arbitrary | E7: -99999 | F7: 99999 | H7: Leaf wetness | I7: dimensionless | M7: =VLOOKUP(A7,naming_lookup!$C$1:$G$40,3,FALSE) -> -99999
A8: NDVI_649IN | B8: Photosynthetic photon flux density incoming @649 nm | C8: micromol / m^2 / s | D8: energy flux | E8: 0 | F8: 500 | H8: Normalized Difference Vegetation Index | I8: micromol m-2 s-1 | M8: =VLOOKUP(A8,naming_lookup!$C$1:$G$40,3,FALSE) -> 0
A9: NDVI_649OUT | B9: Photosynthetic photon flux density reflected @649 nm | C9: micromol / m^2 / s | D9: energy flux | E9: 0 | F9: 500 | H9: Normalized Difference Vegetation Index | I9: micromol m-2 s-1 | M9: =VLOOKUP(A9,naming_lookup!$C$1:$G$40,3,FALSE) -> 0
A10: NDVI_797IN | B10: Photosynthetic photon flux density incoming @797 nm | C10: micromol / m^2 / s | D10: energy flux | E10: 0 | F10: 500 | H10: Normalized Difference Vegetation Index | I10: micromol m-2 s-1 | M10: =VLOOKUP(A10,naming_lookup!$C$1:$G$40,3,FALSE) -> 0
A11: NDVI_797OUT | B11: Photosynthetic photon flux density reflected @797 nm | C11: micromol / m^2 / s | D11: energy flux | E11: 0 | F11: 500 | H11: Normalized Difference Vegetation Index | I11: micromol m-2 s-1 | M11: =VLOOKUP(A11,naming_lookup!$C$1:$G$40,3,FALSE) -> 0
A12: P | B12: Precipitation | C12: m | D12: height | E12: 0 | F12: 50 | G12: P | H12: Precipitation | I12: mm/30 mins | M12: =VLOOKUP(A12,naming_lookup!$C$1:$G$40,3,FALSE) -> 0 | N12: _x000D_ This parameter is the accumulated liquid and frozen water, comprising rain and snow, that falls to the Earth's surface. It is the sum of large-scale precipitation and convective precipitation. Large-scale precipitation is generated by the cloud scheme in the ECMWF Integrated Forecasting System (IFS). The cloud scheme represents the formation and dissipation of clouds and large-scale precipitation due to changes in atmospheric quantities (such as pressure, temperature and moisture) predicted directly by the IFS at spatial scales of the grid box or larger. Convective precipitation is generated by the convection scheme in the IFS, which represents convection at spatial scales smaller than the grid box. See further information. This parameter does not include fog, dew or the precipitation that evaporates in the atmosphere before it lands at the surface of the Earth._x000D_ _x000D_ This parameter is the total amount of water accumulated over a particular time period which depends on the data extracted. The units of this parameter are depth in metres of water equivalent. It is the depth the water would have if it were spread evenly over the grid box._x000D_ _x000D_ Care should be taken when comparing model parameters with observations, because observations are often local to a particular point in space and time, rather than representing averages over a model grid box. [NOTE: See 228228 for the equivalent parameter in "kg m-2"] | O12: m
A13: PA | B13: Atmospheric pressure | C13: kPa | D13: pressure | E13: 90 | F13: 130 | G13: PA | H13: Atmospheric pressure | I13: kPa | M13: =VLOOKUP(A13,naming_lookup!$C$1:$G$40,3,FALSE) -> 90 | N13: This parameter is the pressure (force per unit area) of the atmosphere on the surface of land, sea and in-land water._x000D_ _x000D_ It is a measure of the weight of all the air in a column vertically above the area of the Earth's surface represented at a fixed point._x000D_ _x000D_ Surface pressure is often used in combination with temperature to calculate air density._x000D_ _x000D_ The strong variation of pressure with altitude makes it difficult to see the low and high pressure systems over mountainous areas, so mean sea level pressure, rather than surface pressure, is normally used for this purpose._x000D_ _x000D_ The units of this parameter are Pascals (Pa). Surface pressure is often measured in hPa and sometimes is presented in the old units of millibars, mb (1 hPa = 1 mb= 100 Pa). | O13: Pa
A14: PPFD_DIF | B14: Photosynthetic photon flux density diffuse | C14: micromol / m^2 / s | D14: energy flux | E14: 0 | F14: 2200 | G14: PPFD_DIF | H14: Diffuse incoming PPFD (400-700 nm) | I14: micromol m-2 s-1 | J14: surface_diffuse_downwelling_photosynthetic_radiative_flux_in_air | K14: The surface called "surface" means the lower boundary of the atmosphere. Downwelling radiation is radiation from above. It does not mean "net downward". The sign convention is that "upwelling" is positive upwards and "downwelling" is positive downwards. "Photosynthetic" radiation is the part of the spectrum which is used in photosynthesis e.g. 400-700 nm. "Diffuse" radiation is radiation that has been scattered by gas molecules in the atmosphere and by particles such as cloud droplets and aerosols. The range of wavelengths could be specified precisely by the bounds of a coordinate of radiation_wavelength. When thought of as being incident on a surface, a radiative flux is sometimes called "irradiance". In addition, it is identical with the quantity measured by a cosine-collector light-meter and sometimes called "vector irradiance". In accordance with common usage in geophysical disciplines, "flux" implies per unit area, called "flux density" in physics. | L14: W m-2 | M14: =VLOOKUP(A14,naming_lookup!$C$1:$G$40,3,FALSE) -> 0
A15: PPFD_IN | B15: Photosynthetic photon flux density incoming | C15: micromol / m^2 / s | D15: energy flux | E15: 0 | F15: 2200 | G15: PPFD_IN | H15: Photosynthetic Photon Flux Density (400-700 nm) | I15: micromol m-2 s-1 | M15: =VLOOKUP(A15,naming_lookup!$C$1:$G$40,3,FALSE) -> 0
A16: PPFD_OUT | B16: Photosynthetic photon flux density outgoing | C16: micromol / m^2 / s | D16: energy flux | E16: 0 | F16: 2200 | G16: PPFD_OUT | H16: Reflected PPFD (400-700 nm) | I16: micromol m-2 s-1 | J16: surface_upwelling_photosynthetic_photon_flux_in_air | K16: The surface called "surface" means the lower boundary of the atmosphere. Upwelling radiation is radiation from below. It does not mean "net upward". The sign convention is that "upwelling" is positive upwards and "downwelling" is positive downwards. "Photosynthetic" radiation is the part of the spectrum which is used in photosynthesis e.g. 400-700 nm. The range of wavelengths could be specified precisely by the bounds of a coordinate of radiation_wavelength. A photon flux is specified in terms of numbers of photons expressed in moles. In accordance with common usage in geophysical disciplines, "flux" implies per unit area, called "flux density" in physics. | L16: mol m-2 s-1 | M16: =VLOOKUP(A16,naming_lookup!$C$1:$G$40,3,FALSE) -> 0
A17: RG | B17: Total global radiation | C17: W / m^2 | D17: energy flux | E17: 0 | F17: 1200 | I17: W m-2 | M17: =VLOOKUP(A17,naming_lookup!$C$1:$G$40,3,FALSE) -> 0 | N17: This parameter is the amount of solar radiation (also known as shortwave radiation) that reaches a horizontal plane at the surface of the Earth. This parameter comprises both direct and diffuse solar radiation._x000D_ _x000D_ Radiation from the Sun (solar, or shortwave, radiation) is partly reflected back to space by clouds and particles in the atmosphere (aerosols) and some of it is absorbed. The rest is incident on the Earth's surface (represented by this parameter). See further documentation._x000D_ _x000D_ To a reasonably good approximation, this parameter is the model equivalent of what would be measured by a pyranometer (an instrument used for measuring solar radiation) at the surface. However, care should be taken when comparing model parameters with observations, because observations are often local to a particular point in space and time, rather than representing averages over a model grid box._x000D_ _x000D_ This parameter is accumulated over a particular time period which depends on the data extracted. The units are joules per square metre (J m-2). To convert to watts per square metre (W m-2), the accumulated values should be divided by the accumulation period expressed in seconds. The ECMWF convention for vertical fluxes is positive downwards. | O17: J m-2
A18: RH | B18: Relative humidity | C18: percent | D18: humidity | E18: 30 | F18: 120 | G18: RH | H18: Relative humidity | I18: % | M18: =VLOOKUP(A18,naming_lookup!$C$1:$G$40,3,FALSE) -> 30 | N18: _x000D_ This parameter is the water vapour pressure as a percentage of the value at which the air becomes saturated (the point at which water vapour begins to condense into liquid water or deposition into ice)._x000D_ _x000D_ For temperatures over 0degree_C (273.15 K) it is calculated for saturation over water. At temperatures below -23degree_C it is calculated for saturation over ice. Between -23degree_C and 0degree_C this parameter is calculated by interpolating between the ice and water values using a quadratic function. | O18: %
A19: RN | B19: Net radiation | C19: W / m^2 | D19: energy flux | E19: -500 | F19: 1200 | H19: Net radiation (including SW and LW components) | I19: W m-2 | M19: =VLOOKUP(A19,naming_lookup!$C$1:$G$40,3,FALSE) -> -500 | N19: This parameter is the amount of solar radiation (also known as shortwave radiation) that reaches a horizontal plane at the surface of the Earth (both direct and diffuse) minus the amount reflected by the Earth's surface (which is governed by the albedo)._x000D_ _x000D_ Radiation from the Sun (solar, or shortwave, radiation) is partly reflected back to space by clouds and particles in the atmosphere (aerosols) and some of it is absorbed. The remainder is incident on the Earth's surface, where some of it is reflected. See further documentation._x000D_ _x000D_ This parameter is accumulated over a particular time period which depends on the data extracted. The units are joules per square metre (J m-2). To convert to watts per square metre (W m-2), the accumulated values should be divided by the accumulation period expressed in seconds. The ECMWF convention for vertical fluxes is positive downwards. | O19: J m-2
A20: SW_IN | B20: ShortWave incoming radiation | C20: W / m^2 | D20: energy flux | E20: 0 | F20: 1200 | G20: SW_IN | H20: Incoming Shortwave radiation (in the range from 0.3 to 4.5 micron) | I20: W m-2 | J20: surface_downwelling_shortwave_flux_in_air | K20: The surface called "surface" means the lower boundary of the atmosphere. Downwelling radiation is radiation from above. It does not mean "net downward". The sign convention is that "upwelling" is positive upwards and "downwelling" is positive downwards. The term "shortwave" means shortwave radiation. Surface downwelling shortwave is the sum of direct and diffuse solar radiation incident on the surface, and is sometimes called "global radiation". When thought of as being incident on a surface, a radiative flux is sometimes called "irradiance". In addition, it is identical with the quantity measured by a cosine-collector light-meter and sometimes called "vector irradiance". In accordance with common usage in geophysical disciplines, "flux" implies per unit area, called "flux density" in physics. | L20: W m-2 | M20: =VLOOKUP(A20,naming_lookup!$C$1:$G$40,3,FALSE) -> 0 | N20: This parameter is the amount of solar radiation (also known as shortwave radiation) that reaches a horizontal plane at the surface of the Earth. This parameter comprises both direct and diffuse solar radiation._x000D_ _x000D_ Radiation from the Sun (solar, or shortwave, radiation) is partly reflected back to space by clouds and particles in the atmosphere (aerosols) and some of it is absorbed. The rest is incident on the Earth's surface (represented by this parameter). See further documentation._x000D_ _x000D_ To a reasonably good approximation, this parameter is the model equivalent of what would be measured by a pyranometer (an instrument used for measuring solar radiation) at the surface. However, care should be taken when comparing model parameters with observations, because observations are often local to a particular point in space and time, rather than representing averages over a model grid box._x000D_ _x000D_ This parameter is accumulated over a particular time period which depends on the data extracted. The units are joules per square metre (J m-2). To convert to watts per square metre (W m-2), the accumulated values should be divided by the accumulation period expressed in seconds. The ECMWF convention for vertical fluxes is positive downwards. | O20: J m-2
A21: SW_OUT | B21: ShortWave outgoing radiation | C21: W / m^2 | D21: energy flux | E21: 0 | F21: 300 | G21: SW_OUT | H21: Outgoing Shortwave radiation (in the range from 0.3 to 4.5 micron) | I21: W m-2 | J21: surface_upwelling_shortwave_flux_in_air | K21: The surface called "surface" means the lower boundary of the atmosphere. The term "shortwave" means shortwave radiation. Upwelling radiation is radiation from below. It does not mean "net upward". The sign convention is that "upwelling" is positive upwards and "downwelling" is positive downwards. When thought of as being incident on a surface, a radiative flux is sometimes called "irradiance". In addition, it is identical with the quantity measured by a cosine-collector light-meter and sometimes called "vector irradiance". In accordance with common usage in geophysical disciplines, "flux" implies per unit area, called "flux density" in physics. | L21: W m-2 | M21: =VLOOKUP(A21,naming_lookup!$C$1:$G$40,3,FALSE) -> 0
A22: SWC | B22: Soil water content | C22: % | D22: soil moisture | E22: 0 | F22: 100 | G22: SWC | H22: Soil water content | I22: % | J22: volume_fraction_of_condensed_water_in_soil | K22: "Volume fraction" is used in the construction "volume_fraction_of_X_in_Y", where X is a material constituent of Y. It is evaluated as the volume of X divided by the volume of Y (including X). It may be expressed as a fraction, a percentage, or any other dimensionless representation of a fraction. The phrase "condensed_water" means liquid and ice. | L22: dimensionless | M22: =VLOOKUP(A22,naming_lookup!$C$1:$G$40,3,FALSE) -> 0 | N22: This parameter is the volume of water in soil layer 1 (0 - 7cm, the surface is at 0cm)._x000D_ _x000D_ The ECMWF Integrated Forecasting System model has a four-layer representation of soil:_x000D_ Layer 1: 0 - 7cm_x000D_ Layer 2: 7 - 28cm_x000D_ Layer 3: 28 - 100cm_x000D_ Layer 4: 100 - 289cm_x000D_ _x000D_ The volumetric soil water is associated with the soil texture (or classification), soil depth, and the underlying groundwater level. | O22: m3 m-3
A23: TA | B23: Air temperature | C23: degree_C | D23: temperature | E23: -40 | F23: 50 | G23: TA | H23: Air temperature | I23: degC | M23: =VLOOKUP(A23,naming_lookup!$C$1:$G$40,3,FALSE) -> -40 | N23: _x000D_ This parameter is the temperature of air at 2m above the surface of land, sea or in-land waters._x000D_ _x000D_ 2m temperature is calculated by interpolating between the lowest model level and the Earth's surface, taking account of the atmospheric conditions. See further information ._x000D_ _x000D_ This parameter has units of kelvin (K). Temperature measured in kelvin can be converted to degrees Celsius (degree_C) by subtracting 273.15._x000D_ _x000D_ Please note that the encodings listed here for s2s & uerra (which includes encodings for carra/cerra) include entries for Mean 2 metre temperature. The specific encoding for Mean 2 metre temperature can be found in 228004. | O23: K
A24: TS | B24: Soil temperature | C24: degree_C | D24: temperature | E24: -20 | F24: 50 | G24: TS | H24: Soil temperature | I24: degC | J24: soil_temperature | K24: Soil temperature is the bulk temperature of the soil, not the surface (skin) temperature. "Soil" means the near-surface layer where plants sink their roots. For subsurface temperatures that extend beneath the soil layer or in areas where there is no surface soil layer, the standard name temperature_in_ground should be used. It is strongly recommended that a variable with this standard name should have a units_metadata attribute, with one of the values "on-scale" or "difference", whichever is appropriate for the data, because it is essential to know whether the temperature is on-scale (meaning relative to the origin of the scale indicated by the units) or refers to temperature differences (implying that the origin of the temperature scale is irrelevant), in order to convert the units correctly (cf. https://cfconventions.org/cf-conventions/cf-conventions.html#temperature-units). | L24: K | M24: =VLOOKUP(A24,naming_lookup!$C$1:$G$40,3,FALSE) -> -20 | N24: This parameter is the temperature of the soil at level 1 (in the middle of layer 1)._x000D_ _x000D_ The ECMWF Integrated Forecasting System (IFS) has a four-layer representation of soil, where the surface is at 0cm:_x000D_ _x000D_ Layer 1: 0 - 7cm_x000D_ Layer 2: 7 - 28cm_x000D_ Layer 3: 28 - 100cm_x000D_ Layer 4: 100 - 289cm_x000D_ _x000D_ Soil temperature is set at the middle of each layer, and heat transfer is calculated at the interfaces between them. It is assumed that there is no heat transfer out of the bottom of the lowest layer._x000D_ _x000D_ This parameter has units of Kelvin (K). Temperature measured in Kelvin can be converted to degrees Celsius (degree_C) by subtracting 273.15. | O24: K
A25: WD | B25: Wind direction | C25: degree | D25: energy flux | E25: 0 | F25: 360 | G25: WD | H25: Wind direction | I25: degree | L25: degree | M25: =VLOOKUP(A25,naming_lookup!$C$1:$G$40,3,FALSE) -> 0 | O25: degree
A26: WS | B26: Wind speed | C26: W / m^2 | D26: energy flux | E26: 0 | F26: 30 | G26: WS | H26: Wind speed | I26: m s-1 | M26: =VLOOKUP(A26,naming_lookup!$C$1:$G$40,3,FALSE) -> 0 | N26: This parameter is the horizontal speed of the wind, or movement of air, at a height of ten metres above the surface of the Earth. The units of this parameter are metres per second._x000D_ _x000D_ Care should be taken when comparing this parameter with observations, because wind observations vary on small space and time scales and are affected by the local terrain, vegetation and buildings that are represented only on average in the ECMWF Integrated Forecasting System._x000D_ _x000D_ The eastward and northward components of the horizontal wind at 10m are also available as parameters. | O26: m s-1
A27: WTD | B27: Water table depth | C27: m | D27: height | E27: -10 | F27: 10 | G27: WTD | H27: Water table depth | I27: m | J27: water_table_depth | K27: Depth is the vertical distance below the surface. The water table is the surface below which the soil is saturated with water such that all pore spaces are filled. | L27: m | M27: =VLOOKUP(A27,naming_lookup!$C$1:$G$40,3,FALSE) -> -10
